[2025-08-06T02:22:04.081+0000] {local_task_job_runner.py:120} INFO - ::group::Pre task execution logs
[2025-08-06T02:22:04.093+0000] {taskinstance.py:2076} INFO - Dependencies all met for dep_context=non-requeueable deps ti=<TaskInstance: mysql_to_s3_metadata_dag.extract_holidays_events manual__2025-08-06T02:15:42.637423+00:00 [queued]>
[2025-08-06T02:22:04.097+0000] {taskinstance.py:2076} INFO - Dependencies all met for dep_context=requeueable deps ti=<TaskInstance: mysql_to_s3_metadata_dag.extract_holidays_events manual__2025-08-06T02:15:42.637423+00:00 [queued]>
[2025-08-06T02:22:04.097+0000] {taskinstance.py:2306} INFO - Starting attempt 2 of 2
[2025-08-06T02:22:04.102+0000] {taskinstance.py:2330} INFO - Executing <Task(PythonOperator): extract_holidays_events> on 2025-08-06 02:15:42.637423+00:00
[2025-08-06T02:22:04.107+0000] {logging_mixin.py:188} WARNING - /home/***/.local/lib/python3.12/site-packages/***/task/task_runner/standard_task_runner.py:61 DeprecationWarning: This process (pid=558) is multi-threaded, use of fork() may lead to deadlocks in the child.
[2025-08-06T02:22:04.108+0000] {standard_task_runner.py:63} INFO - Started process 560 to run task
[2025-08-06T02:22:04.108+0000] {standard_task_runner.py:90} INFO - Running: ['***', 'tasks', 'run', 'mysql_to_s3_metadata_dag', 'extract_holidays_events', 'manual__2025-08-06T02:15:42.637423+00:00', '--job-id', '11', '--raw', '--subdir', 'DAGS_FOLDER/extract/mysql_to_s3_dag.py', '--cfg-path', '/tmp/tmp3fivkriv']
[2025-08-06T02:22:04.110+0000] {standard_task_runner.py:91} INFO - Job 11: Subtask extract_holidays_events
[2025-08-06T02:22:04.117+0000] {logging_mixin.py:188} WARNING - /home/***/.local/lib/python3.12/site-packages/***/settings.py:195 DeprecationWarning: The sql_alchemy_conn option in [core] has been moved to the sql_alchemy_conn option in [database] - the old setting has been used, but please update your config.
[2025-08-06T02:22:04.138+0000] {task_command.py:426} INFO - Running <TaskInstance: mysql_to_s3_metadata_dag.extract_holidays_events manual__2025-08-06T02:15:42.637423+00:00 [running]> on host 3bffe12d583b
[2025-08-06T02:22:04.172+0000] {taskinstance.py:2648} INFO - Exporting env vars: AIRFLOW_CTX_DAG_OWNER='***' AIRFLOW_CTX_DAG_ID='mysql_to_s3_metadata_dag' AIRFLOW_CTX_TASK_ID='extract_holidays_events' AIRFLOW_CTX_EXECUTION_DATE='2025-08-06T02:15:42.637423+00:00' AIRFLOW_CTX_TRY_NUMBER='2' AIRFLOW_CTX_DAG_RUN_ID='manual__2025-08-06T02:15:42.637423+00:00'
[2025-08-06T02:22:04.173+0000] {taskinstance.py:430} INFO - ::endgroup::
[2025-08-06T02:22:04.183+0000] {base.py:84} INFO - Using connection ID 'mysql_local' for task execution.
[2025-08-06T02:22:04.192+0000] {logging_mixin.py:188} WARNING - /home/***/.local/lib/python3.12/site-packages/***/providers/common/sql/hooks/sql.py:243 UserWarning: pandas only supports SQLAlchemy connectable (engine/connection) or database string URI or sqlite3 DBAPI2 connection. Other DBAPI2 objects are not tested. Please consider using SQLAlchemy.
[2025-08-06T02:22:04.201+0000] {taskinstance.py:441} INFO - ::group::Post task execution logs
[2025-08-06T02:22:04.201+0000] {taskinstance.py:2905} ERROR - Task failed with exception
Traceback (most recent call last):
  File "/home/airflow/.local/lib/python3.12/site-packages/pandas/io/sql.py", line 2262, in execute
    cur.execute(sql, *args)
  File "/home/airflow/.local/lib/python3.12/site-packages/MySQLdb/cursors.py", line 179, in execute
    res = self._query(mogrified_query)
          ^^^^^^^^^^^^^^^^^^^^^^^^^^^^
  File "/home/airflow/.local/lib/python3.12/site-packages/MySQLdb/cursors.py", line 330, in _query
    db.query(q)
  File "/home/airflow/.local/lib/python3.12/site-packages/MySQLdb/connections.py", line 261, in query
    _mysql.connection.query(self, query)
MySQLdb.ProgrammingError: (1146, "Table 'retail_sales.holidays_events' doesn't exist")

The above exception was the direct cause of the following exception:

Traceback (most recent call last):
  File "/home/airflow/.local/lib/python3.12/site-packages/airflow/models/taskinstance.py", line 465, in _execute_task
    result = _execute_callable(context=context, **execute_callable_kwargs)
             ^^^^^^^^^^^^^^^^^^^^^^^^^^^^^^^^^^^^^^^^^^^^^^^^^^^^^^^^^^^^^
  File "/home/airflow/.local/lib/python3.12/site-packages/airflow/models/taskinstance.py", line 432, in _execute_callable
    return execute_callable(context=context, **execute_callable_kwargs)
           ^^^^^^^^^^^^^^^^^^^^^^^^^^^^^^^^^^^^^^^^^^^^^^^^^^^^^^^^^^^^
  File "/home/airflow/.local/lib/python3.12/site-packages/airflow/models/baseoperator.py", line 400, in wrapper
    return func(self, *args, **kwargs)
           ^^^^^^^^^^^^^^^^^^^^^^^^^^^
  File "/home/airflow/.local/lib/python3.12/site-packages/airflow/operators/python.py", line 235, in execute
    return_value = self.execute_callable()
                   ^^^^^^^^^^^^^^^^^^^^^^^
  File "/home/airflow/.local/lib/python3.12/site-packages/airflow/operators/python.py", line 252, in execute_callable
    return self.python_callable(*self.op_args, **self.op_kwargs)
           ^^^^^^^^^^^^^^^^^^^^^^^^^^^^^^^^^^^^^^^^^^^^^^^^^^^^^
  File "/opt/airflow/dags/helpers/extract_load_functions.py", line 12, in extract_from_mysql
    df = mysql_hook.get_pandas_df(query)
         ^^^^^^^^^^^^^^^^^^^^^^^^^^^^^^^
  File "/home/airflow/.local/lib/python3.12/site-packages/airflow/providers/common/sql/hooks/sql.py", line 243, in get_pandas_df
    return psql.read_sql(sql, con=conn, params=parameters, **kwargs)
           ^^^^^^^^^^^^^^^^^^^^^^^^^^^^^^^^^^^^^^^^^^^^^^^^^^^^^^^^^
  File "/home/airflow/.local/lib/python3.12/site-packages/pandas/io/sql.py", line 654, in read_sql
    return pandas_sql.read_query(
           ^^^^^^^^^^^^^^^^^^^^^^
  File "/home/airflow/.local/lib/python3.12/site-packages/pandas/io/sql.py", line 2326, in read_query
    cursor = self.execute(sql, params)
             ^^^^^^^^^^^^^^^^^^^^^^^^^
  File "/home/airflow/.local/lib/python3.12/site-packages/pandas/io/sql.py", line 2274, in execute
    raise ex from exc
pandas.errors.DatabaseError: Execution failed on sql 'SELECT * FROM holidays_events LIMIT 1000': (1146, "Table 'retail_sales.holidays_events' doesn't exist")
[2025-08-06T02:22:04.208+0000] {taskinstance.py:1206} INFO - Marking task as FAILED. dag_id=mysql_to_s3_metadata_dag, task_id=extract_holidays_events, run_id=manual__2025-08-06T02:15:42.637423+00:00, execution_date=20250806T021542, start_date=20250806T022204, end_date=20250806T022204
[2025-08-06T02:22:04.212+0000] {standard_task_runner.py:110} ERROR - Failed to execute job 11 for task extract_holidays_events (Execution failed on sql 'SELECT * FROM holidays_events LIMIT 1000': (1146, "Table 'retail_sales.holidays_events' doesn't exist"); 560)
[2025-08-06T02:22:04.249+0000] {local_task_job_runner.py:240} INFO - Task exited with return code 1
[2025-08-06T02:22:04.258+0000] {taskinstance.py:3498} INFO - 0 downstream tasks scheduled from follow-on schedule check
[2025-08-06T02:22:04.259+0000] {local_task_job_runner.py:222} INFO - ::endgroup::
