[2025-08-06T20:53:27.004+0000] {local_task_job_runner.py:120} INFO - ::group::Pre task execution logs
[2025-08-06T20:53:27.020+0000] {taskinstance.py:2076} INFO - Dependencies all met for dep_context=non-requeueable deps ti=<TaskInstance: test_snowflake_conn.run_snowflake_ping manual__2025-08-06T20:41:27.876573+00:00 [queued]>
[2025-08-06T20:53:27.024+0000] {taskinstance.py:2076} INFO - Dependencies all met for dep_context=requeueable deps ti=<TaskInstance: test_snowflake_conn.run_snowflake_ping manual__2025-08-06T20:41:27.876573+00:00 [queued]>
[2025-08-06T20:53:27.025+0000] {taskinstance.py:2306} INFO - Starting attempt 2 of 2
[2025-08-06T20:53:27.031+0000] {taskinstance.py:2330} INFO - Executing <Task(SnowflakeOperator): run_snowflake_ping> on 2025-08-06 20:41:27.876573+00:00
[2025-08-06T20:53:27.039+0000] {standard_task_runner.py:90} INFO - Running: ['***', 'tasks', 'run', 'test_snowflake_conn', 'run_snowflake_ping', 'manual__2025-08-06T20:41:27.876573+00:00', '--job-id', '72', '--raw', '--subdir', 'DAGS_FOLDER/load/test_snowflake_conn.py', '--cfg-path', '/tmp/tmp19ol3haa']
[2025-08-06T20:53:27.047+0000] {standard_task_runner.py:91} INFO - Job 72: Subtask run_snowflake_ping
[2025-08-06T20:53:27.046+0000] {logging_mixin.py:188} WARNING - /home/***/.local/lib/python3.12/site-packages/***/task/task_runner/standard_task_runner.py:61 DeprecationWarning: This process (pid=4177) is multi-threaded, use of fork() may lead to deadlocks in the child.
[2025-08-06T20:53:27.051+0000] {standard_task_runner.py:63} INFO - Started process 4180 to run task
[2025-08-06T20:53:27.071+0000] {logging_mixin.py:188} WARNING - /home/***/.local/lib/python3.12/site-packages/***/settings.py:195 DeprecationWarning: The sql_alchemy_conn option in [core] has been moved to the sql_alchemy_conn option in [database] - the old setting has been used, but please update your config.
[2025-08-06T20:53:27.107+0000] {task_command.py:426} INFO - Running <TaskInstance: test_snowflake_conn.run_snowflake_ping manual__2025-08-06T20:41:27.876573+00:00 [running]> on host 3bffe12d583b
[2025-08-06T20:53:27.153+0000] {taskinstance.py:2648} INFO - Exporting env vars: AIRFLOW_CTX_DAG_OWNER='***' AIRFLOW_CTX_DAG_ID='test_snowflake_conn' AIRFLOW_CTX_TASK_ID='run_snowflake_ping' AIRFLOW_CTX_EXECUTION_DATE='2025-08-06T20:41:27.876573+00:00' AIRFLOW_CTX_TRY_NUMBER='2' AIRFLOW_CTX_DAG_RUN_ID='manual__2025-08-06T20:41:27.876573+00:00'
[2025-08-06T20:53:27.154+0000] {taskinstance.py:430} INFO - ::endgroup::
[2025-08-06T20:53:27.169+0000] {sql.py:276} INFO - Executing: SELECT CURRENT_VERSION();
[2025-08-06T20:53:27.179+0000] {base.py:84} INFO - Using connection ID 'snowflake_conn_id' for task execution.
[2025-08-06T20:53:27.188+0000] {base.py:84} INFO - Using connection ID 'snowflake_conn_id' for task execution.
[2025-08-06T20:53:27.190+0000] {connection.py:399} INFO - Snowflake Connector for Python Version: 3.10.0, Python Version: 3.12.3, Platform: Linux-6.10.14-linuxkit-aarch64-with-glibc2.36
[2025-08-06T20:53:27.191+0000] {connection.py:1239} INFO - This connection is in OCSP Fail Open Mode. TLS Certificates would be checked for validity and revocation status. Any other Certificate Revocation related exceptions or OCSP Responder failures would be disregarded in favor of connectivity.
[2025-08-06T20:53:28.569+0000] {connection.py:547} WARNING - Certificate did not match expected hostname: mrc18723.aws_us_east_1.snowflakecomputing.com. Certificate: {'subject': ((('commonName', '*.prod3.us-west-2.snowflakecomputing.com'),),), 'subjectAltName': [('DNS', '*.prod3.us-west-2.snowflakecomputing.com'), ('DNS', '*.us-west-2.snowflakecomputing.com'), ('DNS', '*.global.snowflakecomputing.com'), ('DNS', '*.snowflakecomputing.com'), ('DNS', '*.prod3.us-west-2.aws.snowflakecomputing.com')]}
[2025-08-06T20:53:28.570+0000] {connectionpool.py:824} WARNING - Retrying (Retry(total=0, connect=None, read=None, redirect=None, status=None)) after connection broken by 'SSLError(CertificateError("hostname 'mrc18723.aws_us_east_1.snowflakecomputing.com' doesn't match either of '*.prod3.us-west-2.snowflakecomputing.com', '*.us-west-2.snowflakecomputing.com', '*.global.snowflakecomputing.com', '*.snowflakecomputing.com', '*.prod3.us-west-2.aws.snowflakecomputing.com'"))': /session/v1/login-request?request_id=d8105598-0f7c-4e22-b23b-bb7da8c1afd6&databaseName=RETAIL_DB&schemaName=RAW&warehouse=COMPUTE_WH&roleName=ACCOUNTADMIN&request_guid=cf7e3d98-c4b8-4ab7-8dde-99461701eae3
[2025-08-06T20:53:28.838+0000] {connection.py:547} WARNING - Certificate did not match expected hostname: mrc18723.aws_us_east_1.snowflakecomputing.com. Certificate: {'subject': ((('commonName', '*.prod3.us-west-2.snowflakecomputing.com'),),), 'subjectAltName': [('DNS', '*.prod3.us-west-2.snowflakecomputing.com'), ('DNS', '*.us-west-2.snowflakecomputing.com'), ('DNS', '*.global.snowflakecomputing.com'), ('DNS', '*.snowflakecomputing.com'), ('DNS', '*.prod3.us-west-2.aws.snowflakecomputing.com')]}
[2025-08-06T20:53:28.846+0000] {network.py:1029} ERROR - Failed to get the response. Hanging? method: post, url: https://mrc18723.AWS_US_EAST_1.snowflakecomputing.com:443/session/v1/login-request?request_id=d8105598-0f7c-4e22-b23b-bb7da8c1afd6&databaseName=RETAIL_DB&schemaName=RAW&warehouse=COMPUTE_WH&roleName=ACCOUNTADMIN&request_guid=cf7e3d98-c4b8-4ab7-8dde-99461701eae3, headers:{'Content-Type': 'application/json', 'accept': 'application/snowflake', 'User-Agent': 'PythonConnector/3.10.0 (Linux-6.10.14-linuxkit-aarch64-with-glibc2.36) CPython/3.12.3', 'Content-Encoding': 'gzip'}, data: {"data": {"CLIENT_APP_ID": "PythonConnector", "CLIENT_APP_VERSION": "3.10.0", "SVN_REVISION": null, "ACCOUNT_NAME": "mrc18723", "LOGIN_NAME": "MEGHASHREE", "CLIENT_ENVIRONMENT": {"APPLICATION": "AIRFLOW", "OS": "Linux", "OS_VERSION": "Linux-6.10.14-linuxkit-aarch64-with-glibc2.36", "PYTHON_VERSION": "3.12.3", "PYTHON_RUNTIME": "CPython", "PYTHON_COMPILER": "GCC 12.2.0", "OCSP_MODE": "FAIL_OPEN", "TRACING": 20, "LOGIN_TIMEOUT": null, "NETWORK_TIMEOUT": null, "SOCKET_TIMEOUT": null}, "PASSWORD": "**** "SESSION_PARAMETERS": {"CLIENT_PREFETCH_THREADS": 4}}}
[2025-08-06T20:53:30.121+0000] {connection.py:547} WARNING - Certificate did not match expected hostname: mrc18723.aws_us_east_1.snowflakecomputing.com. Certificate: {'subject': ((('commonName', '*.prod3.us-west-2.snowflakecomputing.com'),),), 'subjectAltName': [('DNS', '*.prod3.us-west-2.snowflakecomputing.com'), ('DNS', '*.us-west-2.snowflakecomputing.com'), ('DNS', '*.global.snowflakecomputing.com'), ('DNS', '*.snowflakecomputing.com'), ('DNS', '*.prod3.us-west-2.aws.snowflakecomputing.com')]}
[2025-08-06T20:53:30.123+0000] {connectionpool.py:824} WARNING - Retrying (Retry(total=0, connect=None, read=None, redirect=None, status=None)) after connection broken by 'SSLError(CertificateError("hostname 'mrc18723.aws_us_east_1.snowflakecomputing.com' doesn't match either of '*.prod3.us-west-2.snowflakecomputing.com', '*.us-west-2.snowflakecomputing.com', '*.global.snowflakecomputing.com', '*.snowflakecomputing.com', '*.prod3.us-west-2.aws.snowflakecomputing.com'"))': /session/v1/login-request?request_id=9d97d318-c2e9-42cd-a885-b54538f10d64&databaseName=RETAIL_DB&schemaName=RAW&warehouse=COMPUTE_WH&roleName=ACCOUNTADMIN&request_guid=2663efa0-5a6e-4618-ae1b-1b8ec337d715
[2025-08-06T20:53:30.359+0000] {connection.py:547} WARNING - Certificate did not match expected hostname: mrc18723.aws_us_east_1.snowflakecomputing.com. Certificate: {'subject': ((('commonName', '*.prod3.us-west-2.snowflakecomputing.com'),),), 'subjectAltName': [('DNS', '*.prod3.us-west-2.snowflakecomputing.com'), ('DNS', '*.us-west-2.snowflakecomputing.com'), ('DNS', '*.global.snowflakecomputing.com'), ('DNS', '*.snowflakecomputing.com'), ('DNS', '*.prod3.us-west-2.aws.snowflakecomputing.com')]}
[2025-08-06T20:53:30.363+0000] {network.py:1029} ERROR - Failed to get the response. Hanging? method: post, url: https://mrc18723.AWS_US_EAST_1.snowflakecomputing.com:443/session/v1/login-request?request_id=9d97d318-c2e9-42cd-a885-b54538f10d64&databaseName=RETAIL_DB&schemaName=RAW&warehouse=COMPUTE_WH&roleName=ACCOUNTADMIN&request_guid=2663efa0-5a6e-4618-ae1b-1b8ec337d715, headers:{'Content-Type': 'application/json', 'accept': 'application/snowflake', 'User-Agent': 'PythonConnector/3.10.0 (Linux-6.10.14-linuxkit-aarch64-with-glibc2.36) CPython/3.12.3', 'Content-Encoding': 'gzip'}, data: {"data": {"CLIENT_APP_ID": "PythonConnector", "CLIENT_APP_VERSION": "3.10.0", "SVN_REVISION": null, "ACCOUNT_NAME": "mrc18723", "LOGIN_NAME": "MEGHASHREE", "CLIENT_ENVIRONMENT": {"APPLICATION": "AIRFLOW", "OS": "Linux", "OS_VERSION": "Linux-6.10.14-linuxkit-aarch64-with-glibc2.36", "PYTHON_VERSION": "3.12.3", "PYTHON_RUNTIME": "CPython", "PYTHON_COMPILER": "GCC 12.2.0", "OCSP_MODE": "FAIL_OPEN", "TRACING": 20, "LOGIN_TIMEOUT": null, "NETWORK_TIMEOUT": null, "SOCKET_TIMEOUT": null}, "PASSWORD": "**** "SESSION_PARAMETERS": {"CLIENT_PREFETCH_THREADS": 4}}}
[2025-08-06T20:53:30.365+0000] {taskinstance.py:441} INFO - ::group::Post task execution logs
[2025-08-06T20:53:30.366+0000] {taskinstance.py:2905} ERROR - Task failed with exception
Traceback (most recent call last):
  File "/home/airflow/.local/lib/python3.12/site-packages/snowflake/connector/connection.py", line 1373, in _authenticate
    auth.authenticate(
  File "/home/airflow/.local/lib/python3.12/site-packages/snowflake/connector/auth/_auth.py", line 250, in authenticate
    ret = self._rest._post_request(
          ^^^^^^^^^^^^^^^^^^^^^^^^^
  File "/home/airflow/.local/lib/python3.12/site-packages/snowflake/connector/network.py", line 734, in _post_request
    ret = self.fetch(
          ^^^^^^^^^^^
  File "/home/airflow/.local/lib/python3.12/site-packages/snowflake/connector/network.py", line 843, in fetch
    ret = self._request_exec_wrapper(
          ^^^^^^^^^^^^^^^^^^^^^^^^^^^
  File "/home/airflow/.local/lib/python3.12/site-packages/snowflake/connector/network.py", line 979, in _request_exec_wrapper
    raise e
  File "/home/airflow/.local/lib/python3.12/site-packages/snowflake/connector/network.py", line 895, in _request_exec_wrapper
    self._handle_unknown_error(method, full_url, headers, data, conn)
  File "/home/airflow/.local/lib/python3.12/site-packages/snowflake/connector/network.py", line 1034, in _handle_unknown_error
    Error.errorhandler_wrapper(
  File "/home/airflow/.local/lib/python3.12/site-packages/snowflake/connector/errors.py", line 290, in errorhandler_wrapper
    handed_over = Error.hand_to_other_handler(
                  ^^^^^^^^^^^^^^^^^^^^^^^^^^^^
  File "/home/airflow/.local/lib/python3.12/site-packages/snowflake/connector/errors.py", line 348, in hand_to_other_handler
    connection.errorhandler(connection, cursor, error_class, error_value)
  File "/home/airflow/.local/lib/python3.12/site-packages/snowflake/connector/errors.py", line 221, in default_errorhandler
    raise error_class(
snowflake.connector.errors.OperationalError: 250003: 250003: Failed to get the response. Hanging? method: post, url: https://mrc18723.AWS_US_EAST_1.snowflakecomputing.com:443/session/v1/login-request?request_id=d8105598-0f7c-4e22-b23b-bb7da8c1afd6&databaseName=RETAIL_DB&schemaName=RAW&warehouse=COMPUTE_WH&roleName=ACCOUNTADMIN&request_guid=cf7e3d98-c4b8-4ab7-8dde-99461701eae3

The above exception was the direct cause of the following exception:

Traceback (most recent call last):
  File "/home/airflow/.local/lib/python3.12/site-packages/airflow/models/taskinstance.py", line 465, in _execute_task
    result = _execute_callable(context=context, **execute_callable_kwargs)
             ^^^^^^^^^^^^^^^^^^^^^^^^^^^^^^^^^^^^^^^^^^^^^^^^^^^^^^^^^^^^^
  File "/home/airflow/.local/lib/python3.12/site-packages/airflow/models/taskinstance.py", line 432, in _execute_callable
    return execute_callable(context=context, **execute_callable_kwargs)
           ^^^^^^^^^^^^^^^^^^^^^^^^^^^^^^^^^^^^^^^^^^^^^^^^^^^^^^^^^^^^
  File "/home/airflow/.local/lib/python3.12/site-packages/airflow/models/baseoperator.py", line 400, in wrapper
    return func(self, *args, **kwargs)
           ^^^^^^^^^^^^^^^^^^^^^^^^^^^
  File "/home/airflow/.local/lib/python3.12/site-packages/airflow/providers/common/sql/operators/sql.py", line 282, in execute
    output = hook.run(
             ^^^^^^^^^
  File "/home/airflow/.local/lib/python3.12/site-packages/airflow/providers/snowflake/hooks/snowflake.py", line 389, in run
    with closing(self.get_conn()) as conn:
                 ^^^^^^^^^^^^^^^
  File "/home/airflow/.local/lib/python3.12/site-packages/airflow/providers/snowflake/hooks/snowflake.py", line 287, in get_conn
    conn = connector.connect(**conn_config)
           ^^^^^^^^^^^^^^^^^^^^^^^^^^^^^^^^
  File "/home/airflow/.local/lib/python3.12/site-packages/snowflake/connector/__init__.py", line 55, in Connect
    return SnowflakeConnection(**kwargs)
           ^^^^^^^^^^^^^^^^^^^^^^^^^^^^^
  File "/home/airflow/.local/lib/python3.12/site-packages/snowflake/connector/connection.py", line 442, in __init__
    self.connect(**kwargs)
  File "/home/airflow/.local/lib/python3.12/site-packages/snowflake/connector/connection.py", line 745, in connect
    self.__open_connection()
  File "/home/airflow/.local/lib/python3.12/site-packages/snowflake/connector/connection.py", line 1073, in __open_connection
    self.authenticate_with_retry(self.auth_class)
  File "/home/airflow/.local/lib/python3.12/site-packages/snowflake/connector/connection.py", line 1345, in authenticate_with_retry
    self._authenticate(auth_instance)
  File "/home/airflow/.local/lib/python3.12/site-packages/snowflake/connector/connection.py", line 1417, in _authenticate
    raise auth_op from e
  File "/home/airflow/.local/lib/python3.12/site-packages/snowflake/connector/connection.py", line 1394, in _authenticate
    auth_instance.handle_timeout(
  File "/home/airflow/.local/lib/python3.12/site-packages/snowflake/connector/auth/by_plugin.py", line 212, in handle_timeout
    raise error
snowflake.connector.errors.OperationalError: 250001: 250001: Could not connect to Snowflake backend after 2 attempt(s).Aborting
[2025-08-06T20:53:30.376+0000] {taskinstance.py:1206} INFO - Marking task as FAILED. dag_id=test_snowflake_conn, task_id=run_snowflake_ping, run_id=manual__2025-08-06T20:41:27.876573+00:00, execution_date=20250806T204127, start_date=20250806T205327, end_date=20250806T205330
[2025-08-06T20:53:30.385+0000] {standard_task_runner.py:110} ERROR - Failed to execute job 72 for task run_snowflake_ping (250001: 250001: Could not connect to Snowflake backend after 2 attempt(s).Aborting; 4180)
[2025-08-06T20:53:30.406+0000] {local_task_job_runner.py:240} INFO - Task exited with return code 1
[2025-08-06T20:53:30.418+0000] {taskinstance.py:3498} INFO - 0 downstream tasks scheduled from follow-on schedule check
[2025-08-06T20:53:30.418+0000] {local_task_job_runner.py:222} INFO - ::endgroup::
